<?xml version="1.0" encoding="UTF-8"?>
<testsuite name="Position Mapping"
           tests="5"
           failures="1"
           errors="0"
           skipped="0"
           time="106.802">
  <properties />
            <testcase name="Edit_Record" time="4.957" classname="Module.OrganizationalSetup.TC025_PositionMappingUploadData">
                <failure type="java.lang.AssertionError"
                  message="expected [Record Updated Successfully.] but found [Position Mapping Already Exists]"
              >
<![CDATA[java.lang.AssertionError: expected [Record Updated Successfully.] but found [Position Mapping Already Exists]
  org.testng.Assert.fail(Assert.java:94)
  org.testng.Assert.failNotEquals(Assert.java:496)
  org.testng.Assert.assertEquals(Assert.java:125)
  org.testng.Assert.assertEquals(Assert.java:178)
  org.testng.Assert.assertEquals(Assert.java:188)
  pom.ObjectPages.uiActions.PositionMapping.Test_EditRecord(PositionMapping.java:107)
  Module.OrganizationalSetup.TC025_PositionMappingUploadData.Edit_Record(TC025_PositionMappingUploadData.java:102)
  sun.reflect.NativeMethodAccessorImpl.invoke0(Native Method)
  sun.reflect.NativeMethodAccessorImpl.invoke(Unknown Source)
  sun.reflect.DelegatingMethodAccessorImpl.invoke(Unknown Source)
  java.lang.reflect.Method.invoke(Unknown Source)
  org.testng.internal.MethodInvocationHelper.invokeMethod(MethodInvocationHelper.java:85)
  org.testng.internal.Invoker.invokeMethod(Invoker.java:639)
  org.testng.internal.Invoker.invokeTestMethod(Invoker.java:821)
  org.testng.internal.Invoker.invokeTestMethods(Invoker.java:1131)
  org.testng.internal.TestMethodWorker.invokeTestMethods(TestMethodWorker.java:124)
  org.testng.internal.TestMethodWorker.run(TestMethodWorker.java:108)
  org.testng.TestRunner.privateRun(TestRunner.java:773)
  org.testng.TestRunner.run(TestRunner.java:623)
  org.testng.SuiteRunner.runTest(SuiteRunner.java:357)
  org.testng.SuiteRunner.access$000(SuiteRunner.java:39)
  org.testng.SuiteRunner$SuiteWorker.run(SuiteRunner.java:391)
  org.testng.internal.thread.ThreadUtil$2.call(ThreadUtil.java:64)
  java.util.concurrent.FutureTask.run(Unknown Source)
  java.util.concurrent.ThreadPoolExecutor.runWorker(Unknown Source)
  java.util.concurrent.ThreadPoolExecutor$Worker.run(Unknown Source)
  java.lang.Thread.run(Unknown Source)
]]>
      </failure>

          </testcase>
  
  
            <testcase name="Target_Page" time="63.965" classname="Module.OrganizationalSetup.TC025_PositionMappingUploadData" />
                <testcase name="AddNew_Button" time="5.908" classname="Module.OrganizationalSetup.TC025_PositionMappingUploadData" />
                <testcase name="Login" time="1.633" classname="Module.OrganizationalSetup.TC025_PositionMappingUploadData" />
                <testcase name="Data_Upload" time="30.339" classname="Module.OrganizationalSetup.TC025_PositionMappingUploadData" />
      
</testsuite>
