<?xml version="1.0" encoding="UTF-8"?>
<!-- Generated by org.testng.reporters.JUnitXMLReporter -->
<testsuite hostname="OSO-DTP-057" name="Position Mapping" tests="5" failures="1" timestamp="16 Nov 2017 05:42:57 GMT" time="157.437" errors="0">
  <testcase name="Login" time="1.633" classname="Module.OrganizationalSetup.TC025_PositionMappingUploadData"/>
  <testcase name="Target_Page" time="63.965" classname="Module.OrganizationalSetup.TC025_PositionMappingUploadData"/>
  <testcase name="AddNew_Button" time="5.908" classname="Module.OrganizationalSetup.TC025_PositionMappingUploadData"/>
  <testcase name="Data_Upload" time="30.339" classname="Module.OrganizationalSetup.TC025_PositionMappingUploadData"/>
  <testcase name="Edit_Record" time="4.957" classname="Module.OrganizationalSetup.TC025_PositionMappingUploadData">
    <failure type="java.lang.AssertionError" message="expected [Record Updated Successfully.] but found [Position Mapping Already Exists]">
      <![CDATA[java.lang.AssertionError: expected [Record Updated Successfully.] but found [Position Mapping Already Exists]
	at pom.ObjectPages.uiActions.PositionMapping.Test_EditRecord(PositionMapping.java:107)
	at Module.OrganizationalSetup.TC025_PositionMappingUploadData.Edit_Record(TC025_PositionMappingUploadData.java:102)
	at java.util.concurrent.FutureTask.run(Unknown Source)
	at java.util.concurrent.ThreadPoolExecutor.runWorker(Unknown Source)
	at java.util.concurrent.ThreadPoolExecutor$Worker.run(Unknown Source)
	at java.lang.Thread.run(Unknown Source)
... Removed 21 stack frames]]>
    </failure>
  </testcase> <!-- Edit_Record -->
</testsuite> <!-- Position Mapping -->
