<?xml version="1.0" encoding="UTF-8"?>
<!-- Generated by org.testng.reporters.JUnitReportReporter -->
<testsuite hostname="OSO-DTP-057" name="Module.OrganizationalSetup.TC016_SubDepartmentMasterUploadData" tests="6" failures="1" timestamp="16 Nov 2017 05:49:36 GMT" time="109.966" errors="0">
  <testcase name="Target_Page" time="63.587" classname="Module.OrganizationalSetup.TC016_SubDepartmentMasterUploadData"/>
  <testcase name="Edit_Record" time="10.742" classname="Module.OrganizationalSetup.TC016_SubDepartmentMasterUploadData">
    <failure type="java.lang.AssertionError" message="expected : [Record Updated Successfully] but Found : [Sub Department Name already exists]">
      <![CDATA[java.lang.AssertionError: expected : [Record Updated Successfully] but Found : [Sub Department Name already exists]
	at org.testng.Assert.fail(Assert.java:94)
	at pom.TestBase.CommonMethods.Test_Edit_Record(CommonMethods.java:160)
	at pom.ObjectPages.uiActions.SubDepartmentMaster.Test_EditRecord(SubDepartmentMaster.java:113)
	at Module.OrganizationalSetup.TC016_SubDepartmentMasterUploadData.Edit_Record(TC016_SubDepartmentMasterUploadData.java:102)
	at sun.reflect.NativeMethodAccessorImpl.invoke0(Native Method)
	at sun.reflect.NativeMethodAccessorImpl.invoke(Unknown Source)
	at sun.reflect.DelegatingMethodAccessorImpl.invoke(Unknown Source)
	at java.lang.reflect.Method.invoke(Unknown Source)
	at org.testng.internal.MethodInvocationHelper.invokeMethod(MethodInvocationHelper.java:85)
	at org.testng.internal.Invoker.invokeMethod(Invoker.java:639)
	at org.testng.internal.Invoker.invokeTestMethod(Invoker.java:821)
	at org.testng.internal.Invoker.invokeTestMethods(Invoker.java:1131)
	at org.testng.internal.TestMethodWorker.invokeTestMethods(TestMethodWorker.java:124)
	at org.testng.internal.TestMethodWorker.run(TestMethodWorker.java:108)
	at org.testng.TestRunner.privateRun(TestRunner.java:773)
	at org.testng.TestRunner.run(TestRunner.java:623)
	at org.testng.SuiteRunner.runTest(SuiteRunner.java:357)
	at org.testng.SuiteRunner.access$000(SuiteRunner.java:39)
	at org.testng.SuiteRunner$SuiteWorker.run(SuiteRunner.java:391)
	at org.testng.internal.thread.ThreadUtil$2.call(ThreadUtil.java:64)
	at java.util.concurrent.FutureTask.run(Unknown Source)
	at java.util.concurrent.ThreadPoolExecutor.runWorker(Unknown Source)
	at java.util.concurrent.ThreadPoolExecutor$Worker.run(Unknown Source)
	at java.lang.Thread.run(Unknown Source)
]]>
    </failure>
  </testcase> <!-- Edit_Record -->
  <testcase name="Data_Upload" time="12.172" classname="Module.OrganizationalSetup.TC016_SubDepartmentMasterUploadData"/>
  <testcase name="Login" time="4.070" classname="Module.OrganizationalSetup.TC016_SubDepartmentMasterUploadData"/>
  <testcase name="Data_Upload" time="13.889" classname="Module.OrganizationalSetup.TC016_SubDepartmentMasterUploadData"/>
  <testcase name="AddNew_Button" time="5.506" classname="Module.OrganizationalSetup.TC016_SubDepartmentMasterUploadData"/>
</testsuite> <!-- Module.OrganizationalSetup.TC016_SubDepartmentMasterUploadData -->
