<?xml version="1.0" encoding="UTF-8"?>
<!-- Generated by org.testng.reporters.JUnitReportReporter -->
<testsuite hostname="OSO-DTP-057" name="Module.OrganizationalSetup.TC025_PositionMappingUploadData" tests="5" failures="1" timestamp="16 Nov 2017 05:49:36 GMT" time="118.179" errors="0">
  <testcase name="Edit_Record" time="7.663" classname="Module.OrganizationalSetup.TC025_PositionMappingUploadData">
    <failure type="java.lang.AssertionError" message="expected [Record Updated Successfully.] but found [Position Mapping Already Exists]">
      <![CDATA[java.lang.AssertionError: expected [Record Updated Successfully.] but found [Position Mapping Already Exists]
	at org.testng.Assert.fail(Assert.java:94)
	at org.testng.Assert.failNotEquals(Assert.java:496)
	at org.testng.Assert.assertEquals(Assert.java:125)
	at org.testng.Assert.assertEquals(Assert.java:178)
	at org.testng.Assert.assertEquals(Assert.java:188)
	at pom.ObjectPages.uiActions.PositionMapping.Test_EditRecord(PositionMapping.java:107)
	at Module.OrganizationalSetup.TC025_PositionMappingUploadData.Edit_Record(TC025_PositionMappingUploadData.java:102)
	at sun.reflect.NativeMethodAccessorImpl.invoke0(Native Method)
	at sun.reflect.NativeMethodAccessorImpl.invoke(Unknown Source)
	at sun.reflect.DelegatingMethodAccessorImpl.invoke(Unknown Source)
	at java.lang.reflect.Method.invoke(Unknown Source)
	at org.testng.internal.MethodInvocationHelper.invokeMethod(MethodInvocationHelper.java:85)
	at org.testng.internal.Invoker.invokeMethod(Invoker.java:639)
	at org.testng.internal.Invoker.invokeTestMethod(Invoker.java:821)
	at org.testng.internal.Invoker.invokeTestMethods(Invoker.java:1131)
	at org.testng.internal.TestMethodWorker.invokeTestMethods(TestMethodWorker.java:124)
	at org.testng.internal.TestMethodWorker.run(TestMethodWorker.java:108)
	at org.testng.TestRunner.privateRun(TestRunner.java:773)
	at org.testng.TestRunner.run(TestRunner.java:623)
	at org.testng.SuiteRunner.runTest(SuiteRunner.java:357)
	at org.testng.SuiteRunner.access$000(SuiteRunner.java:39)
	at org.testng.SuiteRunner$SuiteWorker.run(SuiteRunner.java:391)
	at org.testng.internal.thread.ThreadUtil$2.call(ThreadUtil.java:64)
	at java.util.concurrent.FutureTask.run(Unknown Source)
	at java.util.concurrent.ThreadPoolExecutor.runWorker(Unknown Source)
	at java.util.concurrent.ThreadPoolExecutor$Worker.run(Unknown Source)
	at java.lang.Thread.run(Unknown Source)
]]>
    </failure>
  </testcase> <!-- Edit_Record -->
  <testcase name="Target_Page" time="66.128" classname="Module.OrganizationalSetup.TC025_PositionMappingUploadData"/>
  <testcase name="AddNew_Button" time="8.086" classname="Module.OrganizationalSetup.TC025_PositionMappingUploadData"/>
  <testcase name="Login" time="3.771" classname="Module.OrganizationalSetup.TC025_PositionMappingUploadData"/>
  <testcase name="Data_Upload" time="32.531" classname="Module.OrganizationalSetup.TC025_PositionMappingUploadData"/>
</testsuite> <!-- Module.OrganizationalSetup.TC025_PositionMappingUploadData -->
